<sdf version='1.7'>
  <world name='default'>
    <model name='ground_plane'>
      <static>1</static>
      <link name='link'>
        <collision name='collision'>
          <geometry>
            <plane>
              <normal>0 0 1</normal>
              <size>100 100</size>
            </plane>
          </geometry>
          <surface>
            <contact>
              <collide_bitmask>65535</collide_bitmask>
              <ode/>
            </contact>
            <friction>
              <ode>
                <mu>100</mu>
                <mu2>50</mu2>
              </ode>
              <torsional>
                <ode/>
              </torsional>
            </friction>
            <bounce/>
          </surface>
          <max_contacts>10</max_contacts>
        </collision>
        <visual name='visual'>
          <cast_shadows>0</cast_shadows>
          <geometry>
            <plane>
              <normal>0 0 1</normal>
              <size>100 100</size>
            </plane>
          </geometry>
          <material>
            <script>
              <uri>file://media/materials/scripts/gazebo.material</uri>
              <name>Gazebo/Grey</name>
            </script>
          </material>
        </visual>
        <self_collide>0</self_collide>
        <enable_wind>0</enable_wind>
        <kinematic>0</kinematic>
      </link>
    </model>
    <light name='sun' type='directional'>
      <cast_shadows>1</cast_shadows>
      <pose>0 0 10 0 -0 0</pose>
      <diffuse>0.8 0.8 0.8 1</diffuse>
      <specular>0.2 0.2 0.2 1</specular>
      <attenuation>
        <range>1000</range>
        <constant>0.9</constant>
        <linear>0.01</linear>
        <quadratic>0.001</quadratic>
      </attenuation>
      <direction>-0.5 0.1 -0.9</direction>
      <spot>
        <inner_angle>0</inner_angle>
        <outer_angle>0</outer_angle>
        <falloff>0</falloff>
      </spot>
    </light>
    <model name='metal_peg'>
      <link name='link'>
        <pose>0 0 0.031 0 -0 0</pose>
        <inertial>
          <mass>0.0121</mass>
          <inertia>
            <ixx>3.90898e-06</ixx>
            <ixy>0</ixy>
            <ixz>0</ixz>
            <iyy>3.90898e-06</iyy>
            <iyz>0</iyz>
            <izz>6.58845e-08</izz>
          </inertia>
          <pose>0 0 0 0 -0 0</pose>
        </inertial>
        <collision name='collision'>
          <laser_retro>0</laser_retro>
          <max_contacts>10</max_contacts>
          <pose>0 0 0 0 -0 0</pose>
          <geometry>
            <mesh>
              <uri>model://can_coke/meshes/body.dae</uri>
              <scale>1 1 1</scale>
            </mesh>
          </geometry>
          <surface>
            <contact>
              <poissons_ratio>0.305</poissons_ratio>
              <elastic_modulus>2e+11</elastic_modulus>
              <ode>
                <kp>100000</kp>
                <kd>100</kd>
                <max_vel>100</max_vel>
                <min_depth>0.001</min_depth>
              </ode>
            </contact>
            <friction>
              <torsional>
                <coefficient>1</coefficient>
                <use_patch_radius>0</use_patch_radius>
                <surface_radius>0.01</surface_radius>
                <ode/>
              </torsional>
              <ode/>
            </friction>
            <bounce/>
          </surface>
        </collision>
        <visual name='visual'>
          <geometry>
            <mesh>
              <uri>model://can_coke/meshes/body.dae</uri>
              <scale>1 1 1</scale>
            </mesh>
          </geometry>
          <material>
            <script>
              <uri>model://can_coke/materials/scripts</uri>
              <uri>model://can_coke/materials/textures</uri>
              <name>coke</name>
            </script>
          </material>
        </visual>
        <self_collide>0</self_collide>
        <enable_wind>0</enable_wind>
        <kinematic>0</kinematic>
      </link>
    </model>
    <gui fullscreen='0'>
      <camera name='user_camera'>
        <pose>0.45607 -1.42507 4.33727 0 1.52272 2.75087</pose>
        <view_controller>orbit</view_controller>
        <projection_type>perspective</projection_type>
      </camera>
    </gui>
    <gravity>0 0 -9.8</gravity>
    <magnetic_field>6e-06 2.3e-05 -4.2e-05</magnetic_field>
    <atmosphere type='adiabatic'/>
    <physics type='ode'>
      <max_step_size>0.001</max_step_size>
      <real_time_factor>1</real_time_factor>
      <real_time_update_rate>1000</real_time_update_rate>
    </physics>
    <scene>
      <ambient>0.4 0.4 0.4 1</ambient>
      <background>0.7 0.7 0.7 1</background>
      <shadows>1</shadows>
    </scene>
    <wind/>
    <spherical_coordinates>
      <surface_model>EARTH_WGS84</surface_model>
      <latitude_deg>0</latitude_deg>
      <longitude_deg>0</longitude_deg>
      <elevation>0</elevation>
      <heading_deg>0</heading_deg>
    </spherical_coordinates>
    <model name='indy7'>
      <joint name='global' type='fixed'>
        <pose relative_to='__model__'>0 0 0 0 -0 0</pose>
        <parent>world</parent>
        <child>link0</child>
      </joint>
      <link name='link0'>
        <pose relative_to='global'>0 0 0 0 -0 0</pose>
        <inertial>
          <pose>0 0 0 0 -0 0</pose>
          <mass>1.59307</mass>
          <inertia>
            <ixx>0.00572623</ixx>
            <ixy>2.51e-06</ixy>
            <ixz>-0.0001138</ixz>
            <iyy>0.00558959</iyy>
            <iyz>-1.4e-07</iyz>
            <izz>0.00966674</izz>
          </inertia>
        </inertial>
        <collision name='link0_collision'>
          <pose>0 0 0.0375 0 -0 0</pose>
          <geometry>
            <cylinder>
              <length>0.075</length>
              <radius>0.102</radius>
            </cylinder>
          </geometry>
          <surface>
            <contact>
              <ode/>
            </contact>
            <friction>
              <ode>
                <mu>0.2</mu>
                <mu2>0.2</mu2>
              </ode>
              <torsional>
                <ode/>
              </torsional>
            </friction>
            <bounce/>
          </surface>
          <max_contacts>10</max_contacts>
        </collision>
        <visual name='link0_visual'>
          <pose>0 0 0 0 -0 0</pose>
          <geometry>
            <mesh>
              <scale>1 1 1</scale>
              <uri>/home/ghpark/catkin_ws/src/indy-ros/indy7_description/meshes/stl/Indy7_0.stl</uri>
            </mesh>
          </geometry>
          <material>
            <script>
              <name>Gazebo/White</name>
              <uri>file://media/materials/scripts/gazebo.material</uri>
            </script>
          </material>
        </visual>
        <self_collide>0</self_collide>
        <enable_wind>0</enable_wind>
        <kinematic>0</kinematic>
      </link>
      <joint name='joint0' type='revolute'>
        <pose relative_to='link0'>0 0 0.0775 0 -0 0</pose>
        <parent>link0</parent>
        <child>link1</child>
        <axis>
          <xyz>0 0 1</xyz>
          <limit>
            <lower>-3.05433</lower>
            <upper>3.05433</upper>
            <effort>200</effort>
            <velocity>1</velocity>
          </limit>
          <dynamics>
            <spring_reference>0</spring_reference>
            <spring_stiffness>0</spring_stiffness>
          </dynamics>
        </axis>
      </joint>
      <link name='link1'>
        <pose relative_to='joint0'>0 0 0 0 -0 0</pose>
        <inertial>
          <pose>0 0 0 0 -0 0</pose>
          <mass>11.803</mass>
          <inertia>
            <ixx>0.154186</ixx>
            <ixy>-2.35e-06</ixy>
            <ixz>1.739e-05</ixz>
            <iyy>0.12937</iyy>
            <iyz>-0.0485427</iyz>
            <izz>0.0596441</izz>
          </inertia>
        </inertial>
        <collision name='link1_collision'>
          <pose>0 0 0.111 0 -0 0</pose>
          <geometry>
            <cylinder>
              <length>0.222</length>
              <radius>0.075</radius>
            </cylinder>
          </geometry>
          <surface>
            <contact>
              <ode/>
            </contact>
            <friction>
              <ode>
                <mu>0.2</mu>
                <mu2>0.2</mu2>
              </ode>
              <torsional>
                <ode/>
              </torsional>
            </friction>
            <bounce/>
          </surface>
          <max_contacts>10</max_contacts>
        </collision>
        <collision name='link1_collision_1'>
          <pose>0 -0.0545 0.222 1.5708 -0 0</pose>
          <geometry>
            <cylinder>
              <length>0.109</length>
              <radius>0.075</radius>
            </cylinder>
          </geometry>
          <surface>
            <contact>
              <ode/>
            </contact>
            <friction>
              <ode>
                <mu>0.2</mu>
                <mu2>0.2</mu2>
              </ode>
              <torsional>
                <ode/>
              </torsional>
            </friction>
            <bounce/>
          </surface>
          <max_contacts>10</max_contacts>
        </collision>
        <visual name='link1_visual'>
          <pose>0 0 0 0 -0 0</pose>
          <geometry>
            <mesh>
              <scale>1 1 1</scale>
              <uri>/home/ghpark/catkin_ws/src/indy-ros/indy7_description/meshes/stl/Indy7_1.stl</uri>
            </mesh>
          </geometry>
          <material>
            <script>
              <name>Gazebo/White</name>
              <uri>file://media/materials/scripts/gazebo.material</uri>
            </script>
          </material>
        </visual>
        <self_collide>0</self_collide>
        <enable_wind>0</enable_wind>
        <kinematic>0</kinematic>
      </link>
      <joint name='joint1' type='revolute'>
        <pose relative_to='link1'>0 -0.109 0.222 -1.57079 1.57079 3.14159</pose>
        <parent>link1</parent>
        <child>link2</child>
        <axis>
          <xyz>0 0 1</xyz>
          <limit>
            <lower>-3.05433</lower>
            <upper>3.05433</upper>
            <effort>200</effort>
            <velocity>1</velocity>
          </limit>
          <dynamics>
            <spring_reference>0</spring_reference>
            <spring_stiffness>0</spring_stiffness>
          </dynamics>
        </axis>
      </joint>
      <link name='link2'>
        <pose relative_to='joint1'>0 0 0 0 -0 0</pose>
        <inertial>
          <pose>0 0 0 0 -0 0</pose>
          <mass>7.99292</mass>
          <inertia>
            <ixx>0.29357</ixx>
            <ixy>-4e-07</ixy>
            <ixz>1.441e-05</ixz>
            <iyy>0.280941</iyy>
            <iyz>0.0372797</iyz>
            <izz>0.0362061</izz>
          </inertia>
        </inertial>
        <collision name='link2_collision'>
          <pose>-0.225 0 0.09 1.5708 0 -1.5708</pose>
          <geometry>
            <cylinder>
              <length>0.45</length>
              <radius>0.063</radius>
            </cylinder>
          </geometry>
          <surface>
            <contact>
              <ode/>
            </contact>
            <friction>
              <ode>
                <mu>0.2</mu>
                <mu2>0.2</mu2>
              </ode>
              <torsional>
                <ode/>
              </torsional>
            </friction>
            <bounce/>
          </surface>
          <max_contacts>10</max_contacts>
        </collision>
        <collision name='link2_collision_1'>
          <pose>0 0 0.045 0 -0 0</pose>
          <geometry>
            <cylinder>
              <length>0.09</length>
              <radius>0.075</radius>
            </cylinder>
          </geometry>
          <surface>
            <contact>
              <ode/>
            </contact>
            <friction>
              <ode>
                <mu>0.2</mu>
                <mu2>0.2</mu2>
              </ode>
              <torsional>
                <ode/>
              </torsional>
            </friction>
            <bounce/>
          </surface>
          <max_contacts>10</max_contacts>
        </collision>
        <collision name='link2_collision_2'>
          <pose>-0.45 0 0.02975 0 -0 0</pose>
          <geometry>
            <cylinder>
              <length>0.1205</length>
              <radius>0.045</radius>
            </cylinder>
          </geometry>
          <surface>
            <contact>
              <ode/>
            </contact>
            <friction>
              <ode>
                <mu>0.2</mu>
                <mu2>0.2</mu2>
              </ode>
              <torsional>
                <ode/>
              </torsional>
            </friction>
            <bounce/>
          </surface>
          <max_contacts>10</max_contacts>
        </collision>
        <visual name='link2_visual'>
          <pose>0 0 0 0 -0 0</pose>
          <geometry>
            <mesh>
              <scale>1 1 1</scale>
              <uri>/home/ghpark/catkin_ws/src/indy-ros/indy7_description/meshes/stl/Indy7_2.stl</uri>
            </mesh>
          </geometry>
          <material>
            <script>
              <name>Gazebo/White</name>
              <uri>file://media/materials/scripts/gazebo.material</uri>
            </script>
          </material>
        </visual>
        <self_collide>0</self_collide>
        <enable_wind>0</enable_wind>
        <kinematic>0</kinematic>
      </link>
      <joint name='joint2' type='revolute'>
        <pose relative_to='link2'>-0.45 0 -0.0305 0 -0 0</pose>
        <parent>link2</parent>
        <child>link3</child>
        <axis>
          <xyz>0 0 1</xyz>
          <limit>
            <lower>-3.05433</lower>
            <upper>3.05433</upper>
            <effort>200</effort>
            <velocity>1</velocity>
          </limit>
          <dynamics>
            <spring_reference>0</spring_reference>
            <spring_stiffness>0</spring_stiffness>
          </dynamics>
        </axis>
      </joint>
      <link name='link3'>
        <pose relative_to='joint2'>0 0 0 0 -0 0</pose>
        <inertial>
          <pose>0 0 0 0 -0 0</pose>
          <mass>2.99134</mass>
          <inertia>
            <ixx>0.0342459</ixx>
            <ixy>1.49e-06</ixy>
            <ixz>7.24e-06</ixz>
            <iyy>0.0340602</iyy>
            <iyz>0.00186009</iyz>
            <izz>0.00450477</izz>
          </inertia>
        </inertial>
        <collision name='link3_collision'>
          <pose>-0.1335 0 -0.075 1.5708 0 -1.5708</pose>
          <geometry>
            <cylinder>
              <length>0.267</length>
              <radius>0.045</radius>
            </cylinder>
          </geometry>
          <surface>
            <contact>
              <ode/>
            </contact>
            <friction>
              <ode>
                <mu>0.2</mu>
                <mu2>0.2</mu2>
              </ode>
              <torsional>
                <ode/>
              </torsional>
            </friction>
            <bounce/>
          </surface>
          <max_contacts>10</max_contacts>
        </collision>
        <collision name='link3_collision_1'>
          <pose>0 0 -0.0375 0 -0 0</pose>
          <geometry>
            <cylinder>
              <length>0.075</length>
              <radius>0.045</radius>
            </cylinder>
          </geometry>
          <surface>
            <contact>
              <ode/>
            </contact>
            <friction>
              <ode>
                <mu>0.2</mu>
                <mu2>0.2</mu2>
              </ode>
              <torsional>
                <ode/>
              </torsional>
            </friction>
            <bounce/>
          </surface>
          <max_contacts>10</max_contacts>
        </collision>
        <visual name='link3_visual'>
          <pose>0 0 0 0 -0 0</pose>
          <geometry>
            <mesh>
              <scale>1 1 1</scale>
              <uri>/home/ghpark/catkin_ws/src/indy-ros/indy7_description/meshes/stl/Indy7_3.stl</uri>
            </mesh>
          </geometry>
          <material>
            <script>
              <name>Gazebo/White</name>
              <uri>file://media/materials/scripts/gazebo.material</uri>
            </script>
          </material>
        </visual>
        <self_collide>0</self_collide>
        <enable_wind>0</enable_wind>
        <kinematic>0</kinematic>
      </link>
      <joint name='joint3' type='revolute'>
        <pose relative_to='link3'>-0.267 0 -0.075 -1.5708 0 1.5708</pose>
        <parent>link3</parent>
        <child>link4</child>
        <axis>
          <xyz>0 0 1</xyz>
          <limit>
            <lower>-3.05433</lower>
            <upper>3.05433</upper>
            <effort>10</effort>
            <velocity>1</velocity>
          </limit>
          <dynamics>
            <spring_reference>0</spring_reference>
            <spring_stiffness>0</spring_stiffness>
          </dynamics>
        </axis>
      </joint>
      <link name='link4'>
        <pose relative_to='joint3'>0 0 0 0 -0 0</pose>
        <inertial>
          <pose>0 0 0 0 -0 0</pose>
          <mass>2.12317</mass>
          <inertia>
            <ixx>0.00670405</ixx>
            <ixy>3.75e-06</ixy>
            <ixz>1.5e-06</ixz>
            <iyy>0.00279246</iyy>
            <iyz>-0.00127967</iyz>
            <izz>0.00619341</izz>
          </inertia>
        </inertial>
        <collision name='link4_collision'>
          <pose>0 -0.057 0.083 1.5708 -0 0</pose>
          <geometry>
            <cylinder>
              <length>0.114</length>
              <radius>0.045</radius>
            </cylinder>
          </geometry>
          <surface>
            <contact>
              <ode/>
            </contact>
            <friction>
              <ode>
                <mu>0.2</mu>
                <mu2>0.2</mu2>
              </ode>
              <torsional>
                <ode/>
              </torsional>
            </friction>
            <bounce/>
          </surface>
          <max_contacts>10</max_contacts>
        </collision>
        <collision name='link4_collision_1'>
          <pose>0 -0.057 0.083 1.5708 -0 0</pose>
          <geometry>
            <cylinder>
              <length>0.114</length>
              <radius>0.045</radius>
            </cylinder>
          </geometry>
          <surface>
            <contact>
              <ode/>
            </contact>
            <friction>
              <ode>
                <mu>0.2</mu>
                <mu2>0.2</mu2>
              </ode>
              <torsional>
                <ode/>
              </torsional>
            </friction>
            <bounce/>
          </surface>
          <max_contacts>10</max_contacts>
        </collision>
        <collision name='link4_collision_2'>
          <pose>0 0 0.0415 0 -0 0</pose>
          <geometry>
            <cylinder>
              <length>0.083</length>
              <radius>0.045</radius>
            </cylinder>
          </geometry>
          <surface>
            <contact>
              <ode/>
            </contact>
            <friction>
              <ode>
                <mu>0.2</mu>
                <mu2>0.2</mu2>
              </ode>
              <torsional>
                <ode/>
              </torsional>
            </friction>
            <bounce/>
          </surface>
          <max_contacts>10</max_contacts>
        </collision>
        <visual name='link4_visual'>
          <pose>0 0 0 0 -0 0</pose>
          <geometry>
            <mesh>
              <scale>1 1 1</scale>
              <uri>/home/ghpark/catkin_ws/src/indy-ros/indy7_description/meshes/stl/Indy7_4.stl</uri>
            </mesh>
          </geometry>
          <material>
            <script>
              <name>Gazebo/White</name>
              <uri>file://media/materials/scripts/gazebo.material</uri>
            </script>
          </material>
        </visual>
        <self_collide>0</self_collide>
        <enable_wind>0</enable_wind>
        <kinematic>0</kinematic>
      </link>
      <joint name='joint4' type='revolute'>
        <pose relative_to='link4'>0 -0.114 0.083 -1.57079 1.57079 3.14159</pose>
        <parent>link4</parent>
        <child>link5</child>
        <axis>
          <xyz>0 0 1</xyz>
          <limit>
            <lower>-3.05433</lower>
            <upper>3.05433</upper>
            <effort>10</effort>
            <velocity>1</velocity>
          </limit>
          <dynamics>
            <spring_reference>0</spring_reference>
            <spring_stiffness>0</spring_stiffness>
          </dynamics>
        </axis>
      </joint>
      <link name='link5'>
        <pose relative_to='joint4'>0 0 0 0 -0 0</pose>
        <inertial>
          <pose>0 0 0 0 -0 0</pose>
          <mass>2.28865</mass>
          <inertia>
            <ixx>0.00994891</ixx>
            <ixy>1.4e-07</ixy>
            <ixz>3.21e-06</ixz>
            <iyy>0.00978189</iyy>
            <iyz>-0.00093546</iyz>
            <izz>0.00271492</izz>
          </inertia>
        </inertial>
        <collision name='link5_collision'>
          <pose>-0.084 0 0.069 1.5708 0 -1.5708</pose>
          <geometry>
            <cylinder>
              <length>0.168</length>
              <radius>0.045</radius>
            </cylinder>
          </geometry>
          <surface>
            <contact>
              <ode/>
            </contact>
            <friction>
              <ode>
                <mu>0.2</mu>
                <mu2>0.2</mu2>
              </ode>
              <torsional>
                <ode/>
              </torsional>
            </friction>
            <bounce/>
          </surface>
          <max_contacts>10</max_contacts>
        </collision>
        <collision name='link5_collision_1'>
          <pose>0 0 0.0345 0 -0 0</pose>
          <geometry>
            <cylinder>
              <length>0.069</length>
              <radius>0.045</radius>
            </cylinder>
          </geometry>
          <surface>
            <contact>
              <ode/>
            </contact>
            <friction>
              <ode>
                <mu>0.2</mu>
                <mu2>0.2</mu2>
              </ode>
              <torsional>
                <ode/>
              </torsional>
            </friction>
            <bounce/>
          </surface>
          <max_contacts>10</max_contacts>
        </collision>
        <visual name='link5_visual'>
          <pose>0 0 0 0 -0 0</pose>
          <geometry>
            <mesh>
              <scale>1 1 1</scale>
              <uri>/home/ghpark/catkin_ws/src/indy-ros/indy7_description/meshes/stl/Indy7_5.stl</uri>
            </mesh>
          </geometry>
          <material>
            <script>
              <name>Gazebo/White</name>
              <uri>file://media/materials/scripts/gazebo.material</uri>
            </script>
          </material>
        </visual>
        <self_collide>0</self_collide>
        <enable_wind>0</enable_wind>
        <kinematic>0</kinematic>
      </link>
      <joint name='joint5' type='revolute'>
        <pose relative_to='link5'>-0.168 0 0.069 -1.5708 0 1.5708</pose>
        <parent>link5</parent>
        <child>link6</child>
        <axis>
          <xyz>0 0 1</xyz>
          <limit>
            <lower>-3.75246</lower>
            <upper>3.75246</upper>
            <effort>10</effort>
            <velocity>1</velocity>
          </limit>
          <dynamics>
            <spring_reference>0</spring_reference>
            <spring_stiffness>0</spring_stiffness>
          </dynamics>
        </axis>
      </joint>
      <link name='link6'>
        <pose relative_to='joint5'>0 0 0 0 -0 0</pose>
        <inertial>
          <pose>-0.006658 0 0.014648 0 -0 0</pose>
          <mass>0.462414</mass>
          <inertia>
            <ixx>0.0011705</ixx>
            <ixy>1.3e-07</ixy>
            <ixz>0.000293547</ixz>
            <iyy>0.00122729</iyy>
            <iyz>5.1e-07</iyz>
            <izz>0.00082086</izz>
          </inertia>
        </inertial>
        <collision name='link6_collision'>
          <pose>0 0 0.03 0 -0 0</pose>
          <geometry>
            <cylinder>
              <length>0.06</length>
              <radius>0.045</radius>
            </cylinder>
          </geometry>
          <surface>
            <contact>
              <ode/>
            </contact>
            <friction>
              <ode>
                <mu>0.2</mu>
                <mu2>0.2</mu2>
              </ode>
              <torsional>
                <ode/>
              </torsional>
            </friction>
            <bounce/>
          </surface>
          <max_contacts>10</max_contacts>
        </collision>
        <collision name='link6_fixed_joint_lump__rs200_camera_collision_1'>
          <pose>-0.05 0 0.11 3.14159 -1.57079 3.14159</pose>
          <geometry>
            <box>
              <size>0.0078 0.13 0.0192</size>
            </box>
          </geometry>
          <surface>
            <contact>
              <ode>
                <kp>1e+13</kp>
                <kd>1</kd>
              </ode>
            </contact>
            <friction>
              <ode>
                <mu2>1</mu2>
                <fdir1>0 0 0</fdir1>
              </ode>
              <torsional>
                <ode/>
              </torsional>
            </friction>
            <bounce/>
          </surface>
          <max_contacts>10</max_contacts>
        </collision>
        <visual name='link6_visual'>
          <pose>0 0 0 0 -0 0</pose>
          <geometry>
            <mesh>
              <scale>1 1 1</scale>
              <uri>/home/ghpark/catkin_ws/src/indy-ros/indy7_description/meshes/stl/Indy7_6.stl</uri>
            </mesh>
          </geometry>
          <material>
            <script>
              <name>Gazebo/White</name>
              <uri>file://media/materials/scripts/gazebo.material</uri>
            </script>
          </material>
        </visual>
        <visual name='link6_fixed_joint_lump__rs200_camera_visual_1'>
          <pose>-0.05 0 0.11 3.14159 -1.57079 3.14159</pose>
          <geometry>
            <mesh>
              <scale>1 1 1</scale>
              <uri>/home/ghpark/catkin_ws/src/realsense_gazebo_plugin_smc/models/realsense_camera/meshes/realsense.dae</uri>
            </mesh>
          </geometry>
        </visual>
        <self_collide>0</self_collide>
        <enable_wind>0</enable_wind>
        <kinematic>0</kinematic>
        <gravity>1</gravity>
        <sensor name='color' type='camera'>
          <camera name='rs200_camera'>
            <horizontal_fov>1.047</horizontal_fov>
            <image>
              <width>640</width>
              <height>480</height>
              <format>RGB_INT8</format>
            </image>
            <clip>
              <near>0.1</near>
              <far>100</far>
            </clip>
            <noise>
              <type>gaussian</type>
              <mean>0</mean>
              <stddev>0.007</stddev>
            </noise>
          </camera>
          <always_on>1</always_on>
          <update_rate>60</update_rate>
          <visualize>1</visualize>
          <pose>-0.05 0 0.11 3.14159 -1.57079 3.14159</pose>
        </sensor>
        <sensor name='ired1' type='camera'>
          <camera name='rs200_camera'>
            <horizontal_fov>1.047</horizontal_fov>
            <image>
              <width>640</width>
              <height>480</height>
              <format>L_INT8</format>
            </image>
            <clip>
              <near>0.1</near>
              <far>100</far>
            </clip>
            <noise>
              <type>gaussian</type>
              <mean>0</mean>
              <stddev>0.05</stddev>
            </noise>
          </camera>
          <always_on>1</always_on>
          <update_rate>60</update_rate>
          <visualize>0</visualize>
          <pose>-0.05 0 0.11 3.14159 -1.57079 3.14159</pose>
        </sensor>
        <sensor name='ired2' type='camera'>
          <camera name='rs200_camera'>
            <horizontal_fov>1.047</horizontal_fov>
            <image>
              <width>640</width>
              <height>480</height>
              <format>L_INT8</format>
            </image>
            <clip>
              <near>0.1</near>
              <far>100</far>
            </clip>
            <noise>
              <type>gaussian</type>
              <mean>0</mean>
              <stddev>0.05</stddev>
            </noise>
          </camera>
          <always_on>1</always_on>
          <update_rate>60</update_rate>
          <visualize>0</visualize>
          <pose>-0.05 0 0.11 3.14159 -1.57079 3.14159</pose>
        </sensor>
        <sensor name='depth' type='depth'>
          <camera name='rs200_camera'>
            <horizontal_fov>1.047</horizontal_fov>
            <image>
              <width>640</width>
              <height>480</height>
            </image>
            <clip>
              <near>0.1</near>
              <far>100</far>
            </clip>
            <noise>
              <type>gaussian</type>
              <mean>0</mean>
              <stddev>0.1</stddev>
            </noise>
          </camera>
          <always_on>1</always_on>
          <update_rate>60</update_rate>
          <visualize>0</visualize>
          <pose>-0.05 0 0.11 3.14159 -1.57079 3.14159</pose>
        </sensor>
      </link>
      <plugin name='gazebo_ros_control' filename='libgazebo_ros_control.so'>
        <robotNamespace>/</robotNamespace>
      </plugin>
      <static>0</static>
      <plugin name='r200' filename='librealsense_gazebo_plugin.so'>
        <prefix/>
        <robotNamespace>/</robotNamespace>
      </plugin>
      <pose>0 0 0 0 -0 0</pose>
    </model>
    <model name='test2.world'>
      <pose>0.367349 -0.799381 0 0 -0 0</pose>
      <link name='Wall_0'>
        <collision name='Wall_0_Collision'>
          <geometry>
            <box>
              <size>1.25 1 0.5</size>
            </box>
          </geometry>
          <pose>0 0 0.25 0 -0 0</pose>
          <max_contacts>10</max_contacts>
          <surface>
            <contact>
              <ode/>
            </contact>
            <bounce/>
            <friction>
              <torsional>
                <ode/>
              </torsional>
              <ode/>
            </friction>
          </surface>
        </collision>
        <visual name='Wall_0_Visual'>
          <pose>0 0 0.25 0 -0 0</pose>
          <geometry>
            <box>
              <size>1.25 1 0.5</size>
            </box>
          </geometry>
          <material>
            <script>
              <uri>file://media/materials/scripts/gazebo.material</uri>
              <name>Gazebo/Wood</name>
            </script>
            <ambient>1 1 1 1</ambient>
          </material>
          <meta>
            <layer>0</layer>
          </meta>
        </visual>
        <pose>0 -0.314196 0 0 -0 3.14159</pose>
        <self_collide>0</self_collide>
        <enable_wind>0</enable_wind>
        <kinematic>0</kinematic>
      </link>
      <static>1</static>
    </model>
    <model name='apple'>
      <static>0</static>
      <link name='link'>
        <inertial>
          <pose>0.001311 -0.003861 0.036337 1.28659 -0.495792 -1.57796</pose>
          <mass>0.000246595</mass>
          <inertia>
            <ixx>1.53466e-07</ixx>
            <ixy>-1.32349e-23</ixy>
            <ixz>-3.30872e-24</ixz>
            <iyy>1.52372e-07</iyy>
            <iyz>0</iyz>
            <izz>1.50583e-07</izz>
          </inertia>
        </inertial>
        <collision name='collision'>
          <geometry>
            <mesh>
              <uri>model://013_apple/google_16k/textured.obj</uri>
            </mesh>
          </geometry>
          <surface>
            <contact>
              <ode/>
            </contact>
            <bounce/>
            <friction>
              <torsional>
                <ode/>
              </torsional>
              <ode/>
            </friction>
          </surface>
          <max_contacts>10</max_contacts>
        </collision>
        <visual name='visual'>
          <geometry>
            <mesh>
              <uri>model://013_apple/google_16k/textured.obj</uri>
            </mesh>
          </geometry>
          <material>
            <script>
              <uri>model://013_apple/apple.material</uri>
              <name>apple</name>
            </script>
          </material>
        </visual>
        <self_collide>0</self_collide>
        <enable_wind>0</enable_wind>
        <kinematic>0</kinematic>
      </link>
      <pose>-0.05396 -2.27281 0 0 -0 0</pose>
    </model>
    <model name='banana'>
      <static>0</static>
      <link name='link'>
        <inertial>
          <pose>-0.009936 0.004073 0.017127 -1.58732 1.3697 2.8053</pose>
          <mass>0.000171533</mass>
          <inertia>
            <ixx>4.27199e-07</ixx>
            <ixy>-1.32349e-23</ixy>
            <ixz>7.8608e-23</ixz>
            <iyy>4.10766e-07</iyy>
            <iyz>2.40496e-23</iyz>
            <izz>4.07539e-08</izz>
          </inertia>
        </inertial>
        <collision name='collision'>
          <geometry>
            <mesh>
              <uri>model://011_banana/google_16k/textured.obj</uri>
            </mesh>
          </geometry>
          <surface>
            <contact>
              <ode/>
            </contact>
            <bounce/>
            <friction>
              <torsional>
                <ode/>
              </torsional>
              <ode/>
            </friction>
          </surface>
          <max_contacts>10</max_contacts>
        </collision>
        <visual name='visual'>
          <geometry>
            <mesh>
              <uri>model://011_banana/google_16k/textured.obj</uri>
            </mesh>
          </geometry>
          <material>
            <script>
              <uri>model://011_banana/banana.material</uri>
              <name>banana</name>
            </script>
          </material>
        </visual>
        <self_collide>0</self_collide>
        <enable_wind>0</enable_wind>
        <kinematic>0</kinematic>
      </link>
      <pose>-0.156395 -2.1375 0 0 -0 0</pose>
    </model>
    <model name='scissors'>
      <static>0</static>
      <link name='link'>
        <inertial>
          <pose>0.014592 0.003162 0.007401 1.11247 -1.55904 -2.99353</pose>
          <mass>4.68014e-05</mass>
          <inertia>
            <ixx>8.69433e-08</ixx>
            <ixy>-2.06795e-25</ixy>
            <ixz>4.05835e-24</ixz>
            <iyy>7.1021e-08</iyy>
            <iyz>1.03331e-23</iyz>
            <izz>1.69326e-08</izz>
          </inertia>
        </inertial>
        <collision name='collision'>
          <geometry>
            <mesh>
              <uri>model://037_scissors/google_16k/textured.obj</uri>
            </mesh>
          </geometry>
          <surface>
            <contact>
              <ode/>
            </contact>
            <bounce/>
            <friction>
              <torsional>
                <ode/>
              </torsional>
              <ode/>
            </friction>
          </surface>
          <max_contacts>10</max_contacts>
        </collision>
        <visual name='visual'>
          <geometry>
            <mesh>
              <uri>model://037_scissors/google_16k/textured.obj</uri>
            </mesh>
          </geometry>
          <material>
            <script>
              <uri>model://037_scissors/scissors.material</uri>
              <name>scissors</name>
            </script>
          </material>
        </visual>
        <self_collide>0</self_collide>
        <enable_wind>0</enable_wind>
        <kinematic>0</kinematic>
      </link>
      <pose>0.021188 -2.05517 0 0 -0 0</pose>
    </model>
    <state world_name='default'>
      <sim_time>409 218000000</sim_time>
      <real_time>414 697273139</real_time>
      <wall_time>1639288902 297988880</wall_time>
      <iterations>409218</iterations>
      <model name='apple'>
        <pose>-0.000833 -0.800177 0.500379 0.003622 -0.000583 0.006455</pose>
        <scale>1 1 1</scale>
        <link name='link'>
          <pose>-0.000833 -0.800177 0.500379 0.003622 -0.000583 0.006455</pose>
          <velocity>0 0 0 0 -0 0</velocity>
          <acceleration>0 0 -9.8 0 -0 0</acceleration>
          <wrench>0 0 -0.002417 0 -0 0</wrench>
        </link>
      </model>
      <model name='banana'>
        <pose>0.285465 -0.793621 0.500535 -0.012846 -0.027028 -2.56198</pose>
        <scale>1 1 1</scale>
        <link name='link'>
          <pose>0.285465 -0.793621 0.500535 -0.012846 -0.027028 -2.56198</pose>
          <velocity>-0.001938 -0.000633 0.002982 -0.085424 0.068966 0.033055</velocity>
          <acceleration>-0.701488 3.87751 -0.859544 -1.54835 0.047219 2.11107</acceleration>
          <wrench>-0.00012 0.000665 -0.000147 0 -0 0</wrench>
        </link>
      </model>
      <model name='ground_plane'>
        <pose>0 0 0 0 -0 0</pose>
        <scale>1 1 1</scale>
        <link name='link'>
          <pose>0 0 0 0 -0 0</pose>
          <velocity>0 0 0 0 -0 0</velocity>
          <acceleration>0 0 0 0 -0 0</acceleration>
          <wrench>0 0 0 0 -0 0</wrench>
        </link>
      </model>
      <model name='indy7'>
        <pose>-0 0 0 -2.7e-05 -0 -0</pose>
        <scale>1 1 1</scale>
        <link name='link0'>
          <pose>-0 0 0 -2.7e-05 -0 -0</pose>
          <velocity>-5e-06 6e-06 -3e-06 0.001412 -0.000528 -0</velocity>
          <acceleration>-0.001934 0.00022 -0.002044 2.17344 -0.308692 1.9e-05</acceleration>
          <wrench>-0.003081 0.000351 -0.003256 0 -0 0</wrench>
        </link>
        <link name='link1'>
          <pose>0 2e-06 0.0775 6.3e-05 1e-06 -7e-06</pose>
          <velocity>-3e-06 -0.00016 6e-06 -0.003093 0.001313 -0.005388</velocity>
          <acceleration>-0.009125 -0.171124 0.004498 1.30252 0.744793 1.50338</acceleration>
          <wrench>-0.107697 -2.01977 0.053093 0 -0 0</wrench>
        </link>
        <link name='link2'>
          <pose>-1e-06 -0.109013 0.299493 1.70121 1.57028 0.130407</pose>
          <velocity>-0.000262 0.000527 0.000348 -0.003263 0.008263 -0.005281</velocity>
          <acceleration>-0.34258 0.944174 0.555972 3.02954 -1.43188 -0.815973</acceleration>
          <wrench>-2.73821 7.5467 4.44384 0 -0 0</wrench>
        </link>
        <link name='link3'>
          <pose>-0.000229 -0.078543 0.749495 1.66531 1.57008 0.094506</pose>
          <velocity>0.003617 0.002023 0.000249 -0.003293 -0.076837 -0.005292</velocity>
          <acceleration>3.46085 3.3361 0.396298 0.487521 0.220919 -0.979488</acceleration>
          <wrench>10.3526 9.97942 1.18546 0 -0 0</wrench>
        </link>
        <link name='link4'>
          <pose>-0.000417 -0.003562 1.0165 6.5e-05 -0.000711 4.5e-05</pose>
          <velocity>-0.016501 0.002969 -3e-05 -0.003681 -0.076963 0.254895</velocity>
          <acceleration>-23.1621 4.82878 -0.040999 0.462273 -0.653406 -0.9785</acceleration>
          <wrench>-49.1771 10.2523 -0.087048 0 -0 0</wrench>
        </link>
        <link name='link5'>
          <pose>-0.000471 -0.117567 1.09949 1.70033 1.57023 0.129579</pose>
          <velocity>0.00617 0.003287 0.000432 -0.004223 0.142604 0.254908</velocity>
          <acceleration>12.0209 5.32065 0.664805 2.79193 -1.54811 1.71457</acceleration>
          <wrench>27.5115 12.1771 1.52151 0 -0 0</wrench>
        </link>
        <link name='link6'>
          <pose>-0.000562 -0.18658 1.26749 -0.000387 0.000421 2.52645</pose>
          <velocity>0.047918 0.003864 0.000751 0.000675 0.143221 -0.967385</velocity>
          <acceleration>23.5211 -59.5094 0.193879 -1.259 1.02878 -0.21802</acceleration>
          <wrench>10.8765 -27.518 0.089652 0 -0 0</wrench>
        </link>
      </model>
      <model name='metal_peg'>
        <pose>0.981947 1.8448 -0.031545 -0.002761 0.009463 -2.18785</pose>
        <scale>1 1 1</scale>
        <link name='link'>
          <pose>0.981847 1.84451 -0.000546 -0.002761 0.009463 -2.18785</pose>
          <velocity>0 0 0 0 -0 0</velocity>
          <acceleration>1.1e-05 -1.4e-05 -0.00476 0.073156 -0.170734 0.074411</acceleration>
          <wrench>0 -0 -5.8e-05 0 -0 0</wrench>
        </link>
      </model>
      <model name='scissors'>
        <pose>-0.355035 -0.719261 0.514462 -3.14075 -0.028014 -1.02472</pose>
        <scale>1 1 1</scale>
        <link name='link'>
          <pose>-0.355035 -0.719261 0.514462 -3.14075 -0.028014 -1.02472</pose>
          <velocity>0.001474 -0.00169 -0.004693 0.116794 0.101877 -2e-06</velocity>
          <acceleration>0 0 -9.8 -5.1e-05 6.1e-05 0.004103</acceleration>
          <wrench>0 0 -0.000459 0 -0 0</wrench>
        </link>
      </model>
      <model name='test2.world'>
        <pose>0.031894 -0.580852 -0 0 -0 0</pose>
        <scale>1 1 1</scale>
        <link name='Wall_0'>
          <pose>0.031894 -0.895048 -0 0 -0 3.14159</pose>
          <velocity>0 0 0 0 -0 0</velocity>
          <acceleration>0 0 0 0 -0 0</acceleration>
          <wrench>0 0 0 0 -0 0</wrench>
        </link>
      </model>
      <light name='sun'>
        <pose>0 0 10 0 -0 0</pose>
      </light>
    </state>
  </world>
</sdf>
